Workbook

Sheet README
A1: VendorFlow — Supplier Invoice, Payment & Performance System
A2: An Excel control system for recording supplier deliveries and invoices, tracking full and partial payments, and monitoring vendor performance.
B4: PURPOSE
B5: VendorFlow replaces scattered spreadsheets and paper files with one controlled workbook.
B6: Employees record vendors, deliveries, invoices and payments. The workbook calculates balances,
B7: due dates, overdue amounts, aging and supplier performance automatically, checks the data for
B8: errors, prioritises upcoming payments, and reports everything on a management dashboard.
B10: SHEET MAP
B11: Sheet | C11: Who uses it | D11: What it does
B12: Dashboard | C12: Read only | D12: Management view: KPIs, aging, top vendors, monthly trend, charts.
B13: Vendor Master | C13: Enter vendors | D13: One row per supplier. Payment terms and contacts live here.
B14: Invoice & Delivery Log | C14: Enter invoices | D14: One row per supplier invoice / delivery. The core table.
B15: Payments Log | C15: Enter payments | D15: One row per payment. Several rows may point at one invoice.
B16: Payment Planner | C16: Plan payments | D16: Open invoices ranked by urgency, plus cash-requirement summary.
B17: Data Quality & Reconciliation | C17: Read + act | D17: Control totals that must tie, and a list of data exceptions.
B18: Settings | C18: Admin only | D18: Reporting date, aging bands, scoring weights and dropdown lists.
B20: COLOUR LEGEND
B21: Input cell | C21: Type here. Blue text on a light yellow background.
B22: Calculated cell | C22: Do not type here — a formula fills it in.
B23: Linked value | C23: Green text: pulled automatically from another sheet.
B24: Completed / OK | C24: Invoice fully paid, or a check that passed.
B25: Warning | C25: Partly paid, due soon, or something to review.
B26: Overdue / Error | C26: Past the due date, or a data error to fix.
B27: Closed / inactive | C27: No action needed.
B29: DAILY WORKFLOW
B30: 1. New supplier? Add a row on Vendor Master and give it the next free Vendor ID.
B31: 2. Goods arrive? Add a row on Invoice & Delivery Log: Invoice ID, Vendor ID, dates, amount.
B32: 3. Money leaves? Add a row on Payments Log and pick the Invoice ID it settles.
B33: 4. Every morning: open Data Quality & Reconciliation. Every control must read PASS.
B34: 5. Weekly: open Payment Planner, work down the ranked list, enter planned dates and amounts.
B35: 6. Managers: read the Dashboard. It refreshes itself from the three logs.
B37: RULES THAT KEEP THE FILE RELIABLE
B38: • Never delete or overwrite a calculated column — copy the formula down instead.
B39: • Invoice ID and Payment ID must be unique. Payments must quote an Invoice ID that exists.
B40: • Record part payments as separate rows. Never edit the invoice amount to show a part payment.
B41: • Settings!C5 (Reporting Date) drives every overdue and aging calculation. Update it, or replace
... B58: Built with formulas only — no macros, no VBA, no Power Query. Opens in Microsoft Excel, LibreOffice Calc and Google Sheets.

Sheet Dashboard
A1: VendorFlow — Management Dashboard
A2: =" Reporting date: "&TEXT(Settings!$C$5,"yyyy-mm-dd")&" | Currency: "&Settings!$C$6&" | Invoices recorded: "&COUNTA('Invoice & Delivery Log'!$A$8:$A$157)&" | Payments recorded: "&COUNTA('Payments Log'!$A$8:$A$207) -> Reporting date: 2026-09-07 | Currency: USD | Invoices recorded: 60 | Payments recorded: 63
A4: Key Performance Indicators
A5: TOTAL INVOICED | C5: TOTAL PAID | F5: TOTAL OUTSTANDING | H5: TOTAL OVERDUE
A6: =SUM('Invoice & Delivery Log'!$N$8:$N$157) -> 202408.71 | C6: =SUM('Invoice & Delivery Log'!$O$8:$O$157) -> 149164.99 | F6: =SUM('Invoice & Delivery Log'!$P$8:$P$157) -> 53243.72 | H6: =SUM('Invoice & Delivery Log'!$S$8:$S$157) -> 32710.06
A7: ="Across "&COUNTA('Invoice & Delivery Log'!$A$8:$A$157)&" supplier invoices" -> Across 60 supplier invoices | C7: ="Settled through "&COUNTA('Payments Log'!$A$8:$A$207)&" payments" -> Settled through 63 payments | F7: =IFERROR(TEXT(SUM('Invoice & Delivery Log'!$P$8:$P$157)/SUM('Invoice & Delivery Log'!$N$8:$N$157),"0.0%")&" of invoiced value","") -> 26.3% of invoiced value | H7: =IFERROR(TEXT(SUM('Invoice & Delivery Log'!$S$8:$S$157)/SUM('Invoice & Delivery Log'!$P$8:$P$157),"0.0%")&" of the open balance","") -> 61.4% of the open balance
A9: OPEN INVOICES | C9: OVERDUE INVOICES | F9: ON-TIME PAYMENT RATE | H9: AVG DAYS TO PAY
A10: =COUNTIF('Invoice & Delivery Log'!$Y$8:$Y$157,"Yes") -> 18 | C10: =COUNTIFS('Invoice & Delivery Log'!$R$8:$R$157,">0") -> 12 | F10: =IFERROR(COUNTIF('Payments Log'!$N$8:$N$207,"On Time")/(COUNTIF('Payments Log'!$N$8:$N$207,"On Time")+COUNTIF('Payments Log'!$N$8:$N$207,"Late")),"") -> 0.83870968 | H10: =IFERROR(ROUND(AVERAGEIFS('Payments Log'!$L$8:$L$207,'Payments Log'!$L$8:$L$207,">=0"),0),"") -> 19
A11: ="of "&COUNTA('Invoice & Delivery Log'!$A$8:$A$157)&" invoices recorded" -> of 60 invoices recorded | C11: =IFERROR(TEXT(COUNTIFS('Invoice & Delivery Log'!$R$8:$R$157,">0")/COUNTIF('Invoice & Delivery Log'!$Y$8:$Y$157,"Yes"),"0.0%")&" of open invoices","") -> 66.7% of open invoices | F11: ="Payments made on or before the due date" -> Payments made on or before the due date | H11: ="Days from invoice date to payment" -> Days from invoice date to payment
A13: =IF(COUNTIF('Data Quality & Reconciliation'!$F$8:$F$17,"FAIL")>0,"RECONCILIATION CONTROL FAILED — open Data Quality & Reconciliation",IF(COUNTIF('Invoice & Delivery Log'!$W$8:$W$157,"REVIEW")+COUNTIF('Payments Log'!$Q$8:$Q$207,"REVIEW")=0,"All reconciliation controls passed and no data exceptions were found","All reconciliation controls passed — "&(COUNTIF('Invoice & Delivery Log'!$W$8:$W$157,"REVIEW")+COUNTIF('Payments Log'!$Q$8:$Q$207,"REVIEW"))&" data exceptions to review")) -> All reconciliation controls passed — 8 data exceptions to review
A15: Accounts Payable Aging | F15: Payment Status Summary
A16: Aging Bucket | B16: Invoices | C16: Amount | D16: % of Total | F16: Payment Status | G16: Invoices | H16: Invoice Value | I16: % of Value
A17: Not Due Yet | B17: =COUNTIFS('Invoice & Delivery Log'!$T$8:$T$157,$A17) -> 6 | C17: =SUMIFS('Invoice & Delivery Log'!$P$8:$P$157,'Invoice & Delivery Log'!$T$8:$T$157,$A17) -> 21046.05 | D17: =IFERROR($C17/$C$24,"") -> 0.3952776 | F17: Unpaid | G17: =COUNTIFS('Invoice & Delivery Log'!$Q$8:$Q$157,$F17) -> 12 | H17: =SUMIFS('Invoice & Delivery Log'!$N$8:$N$157,'Invoice & Delivery Log'!$Q$8:$Q$157,$F17) -> 47350.33 | I17: =IFERROR($H17/$H$24,"") -> 0.23393425
A18: 1-30 Days Overdue | B18: =COUNTIFS('Invoice & Delivery Log'!$T$8:$T$157,$A18) -> 2 | C18: =SUMIFS('Invoice & Delivery Log'!$P$8:$P$157,'Invoice & Delivery Log'!$T$8:$T$157,$A18) -> 3865.78 | D18: =IFERROR($C18/$C$24,"") -> 0.07260537 | F18: Partially Paid | G18: =COUNTIFS('Invoice & Delivery Log'!$Q$8:$Q$157,$F18) -> 6 | H18: =SUMIFS('Invoice & Delivery Log'!$N$8:$N$157,'Invoice & Delivery Log'!$Q$8:$Q$157,$F18) -> 12700.07 | I18: =IFERROR($H18/$H$24,"") -> 0.062744681
A19: 31-60 Days Overdue | B19: =COUNTIFS('Invoice & Delivery Log'!$T$8:$T$157,$A19) -> 4 | C19: =SUMIFS('Invoice & Delivery Log'!$P$8:$P$157,'Invoice & Delivery Log'!$T$8:$T$157,$A19) -> 5691.73 | D19: =IFERROR($C19/$C$24,"") -> 0.10689956 | F19: Paid | G19: =COUNTIFS('Invoice & Delivery Log'!$Q$8:$Q$157,$F19) -> 41 | H19: =SUMIFS('Invoice & Delivery Log'!$N$8:$N$157,'Invoice & Delivery Log'!$Q$8:$Q$157,$F19) -> 138088.39 | I19: =IFERROR($H19/$H$24,"") -> 0.68222553
A20: 61-90 Days Overdue | B20: =COUNTIFS('Invoice & Delivery Log'!$T$8:$T$157,$A20) -> 2 | C20: =SUMIFS('Invoice & Delivery Log'!$P$8:$P$157,'Invoice & Delivery Log'!$T$8:$T$157,$A20) -> 4839.4 | D20: =IFERROR($C20/$C$24,"") -> 0.09089147 | F20: Overpaid | G20: =COUNTIFS('Invoice & Delivery Log'!$Q$8:$Q$157,$F20) -> 1 | H20: =SUMIFS('Invoice & Delivery Log'!$N$8:$N$157,'Invoice & Delivery Log'!$Q$8:$Q$157,$F20) -> 4269.92 | I20: =IFERROR($H20/$H$24,"") -> 0.021095535
A21: 90+ Days Overdue | B21: =COUNTIFS('Invoice & Delivery Log'!$T$8:$T$157,$A21) -> 4 | C21: =SUMIFS('Invoice & Delivery Log'!$P$8:$P$157,'Invoice & Delivery Log'!$T$8:$T$157,$A21) -> 18313.15 | D21: =IFERROR($C21/$C$24,"") -> 0.34394948 | F21: Check Amount | G21: =COUNTIFS('Invoice & Delivery Log'!$Q$8:$Q$157,$F21) -> 0 | H21: =SUMIFS('Invoice & Delivery Log'!$N$8:$N$157,'Invoice & Delivery Log'!$Q$8:$Q$157,$F21) -> 0 | I21: =IFERROR($H21/$H$24,"") -> 0
A22: No Due Date | B22: =COUNTIFS('Invoice & Delivery Log'!$T$8:$T$157,$A22) -> 0 | C22: =SUMIFS('Invoice & Delivery Log'!$P$8:$P$157,'Invoice & Delivery Log'!$T$8:$T$157,$A22) -> 0 | D22: =IFERROR($C22/$C$24,"") -> 0
A23: Supplier Credit | B23: =COUNTIFS('Invoice & Delivery Log'!$T$8:$T$157,$A23) -> 1 | C23: =SUMIFS('Invoice & Delivery Log'!$P$8:$P$157,'Invoice & Delivery Log'!$T$8:$T$157,$A23) -> -512.39 | D23: =IFERROR($C23/$C$24,"") -> -0.0096234824
A24: Total Outstanding | B24: =SUM($B$17:$B$23) -> 19 | C24: =SUM($C$17:$C$23) -> 53243.72 | D24: 100.0% | F24: Total Invoiced Value | G24: =SUM($G$17:$G$23) -> 60 | H24: =SUM($H$17:$H$23) -> 202408.71 | I24: 100.0%
A26: Top 5 Vendors by Outstanding Balance | F26: Next 5 Payments Due
A27: Vendor Name | B27: Outstanding | C27: Overdue | D27: Rating | F27: Invoice ID | G27: Vendor Name | H27: Due Date | I27: Outstanding
A28: =IFERROR(IF(LARGE('Vendor Master'!$S$8:$S$47,1)<=0,"",INDEX('Vendor Master'!$B$8:$B$47,MATCH(LARGE('Vendor Master'!$S$8:$S$47,1),'Vendor Master'!$S$8:$S$47,0))),"") -> Copperfield Textiles | B28: =IFERROR(IF(LARGE('Vendor Master'!$S$8:$S$47,1)<=0,"",INDEX('Vendor Master'!$L$8:$L$47,MATCH(LARGE('Vendor Master'!$S$8:$S$47,1),'Vendor Master'!$S$8:$S$47,0))),"") -> 17948.79 | C28: =IFERROR(IF(LARGE('Vendor Master'!$S$8:$S$47,1)<=0,"",INDEX('Vendor Master'!$M$8:$M$47,MATCH(LARGE('Vendor Master'!$S$8:$S$47,1),'Vendor Master'!$S$8:$S$47,0))),"") -> 9042.96 | D28: =IFERROR(IF(LARGE('Vendor Master'!$S$8:$S$47,1)<=0,"",INDEX('Vendor Master'!$R$8:$R$47,MATCH(LARGE('Vendor Master'!$S$8:$S$47,1),'Vendor Master'!$S$8:$S$47,0))),"") -> C | F28: =IFERROR(INDEX('Invoice & Delivery Log'!$A$8:$A$157,MATCH(1,'Invoice & Delivery Log'!$Z$8:$Z$157,0)),"") -> INV-1003 | G28: =IFERROR(INDEX('Invoice & Delivery Log'!$C$8:$C$157,MATCH(1,'Invoice & Delivery Log'!$Z$8:$Z$157,0)),"") -> Harborline Logistics | H28: =IFERROR(INDEX('Invoice & Delivery Log'!$M$8:$M$157,MATCH(1,'Invoice & Delivery Log'!$Z$8:$Z$157,0)),"") -> 46121 | I28: =IFERROR(INDEX('Invoice & Delivery Log'!$P$8:$P$157,MATCH(1,'Invoice & Delivery Log'!$Z$8:$Z$157,0)),"") -> 6019.33
A29: =IFERROR(IF(LARGE('Vendor Master'!$S$8:$S$47,2)<=0,"",INDEX('Vendor Master'!$B$8:$B$47,MATCH(LARGE('Vendor Master'!$S$8:$S$47,2),'Vendor Master'!$S$8:$S$47,0))),"") -> Ironbridge Hardware Co. | B29: =IFERROR(IF(LARGE('Vendor Master'!$S$8:$S$47,2)<=0,"",INDEX('Vendor Master'!$L$8:$L$47,MATCH(LARGE('Vendor Master'!$S$8:$S$47,2),'Vendor Master'!$S$8:$S$47,0))),"") -> 10402.56 | C29: =IFERROR(IF(LARGE('Vendor Master'!$S$8:$S$47,2)<=0,"",INDEX('Vendor Master'!$M$8:$M$47,MATCH(LARGE('Vendor Master'!$S$8:$S$47,2),'Vendor Master'!$S$8:$S$47,0))),"") -> 4198.12 | D29: =IFERROR(IF(LARGE('Vendor Master'!$S$8:$S$47,2)<=0,"",INDEX('Vendor Master'!$R$8:$R$47,MATCH(LARGE('Vendor Master'!$S$8:$S$47,2),'Vendor Master'!$S$8:$S$47,0))),"") -> C | F29: =IFERROR(INDEX('Invoice & Delivery Log'!$A$8:$A$157,MATCH(2,'Invoice & Delivery Log'!$Z$8:$Z$157,0)),"") -> INV-1015 | G29: =IFERROR(INDEX('Invoice & Delivery Log'!$C$8:$C$157,MATCH(2,'Invoice & Delivery Log'!$Z$8:$Z$157,0)),"") -> Northwind Paper Supply | H29: =IFERROR(INDEX('Invoice & Delivery Log'!$M$8:$M$157,MATCH(2,'Invoice & Delivery Log'!$Z$8:$Z$157,0)),"") -> 46144 | I29: =IFERROR(INDEX('Invoice & Delivery Log'!$P$8:$P$157,MATCH(2,'Invoice & Delivery Log'!$Z$8:$Z$157,0)),"") -> 2483.16
A30: =IFERROR(IF(LARGE('Vendor Master'!$S$8:$S$47,3)<=0,"",INDEX('Vendor Master'!$B$8:$B$47,MATCH(LARGE('Vendor Master'!$S$8:$S$47,3),'Vendor Master'!$S$8:$S$47,0))),"") -> Harborline Logistics | B30: =IFERROR(IF(LARGE('Vendor Master'!$S$8:$S$47,3)<=0,"",INDEX('Vendor Master'!$L$8:$L$47,MATCH(LARGE('Vendor Master'!$S$8:$S$47,3),'Vendor Master'!$S$8:$S$47,0))),"") -> 7891.53 | C30: =IFERROR(IF(LARGE('Vendor Master'!$S$8:$S$47,3)<=0,"",INDEX('Vendor Master'!$M$8:$M$47,MATCH(LARGE('Vendor Master'!$S$8:$S$47,3),'Vendor Master'!$S$8:$S$47,0))),"") -> 7891.53 | D30: =IFERROR(IF(LARGE('Vendor Master'!$S$8:$S$47,3)<=0,"",INDEX('Vendor Master'!$R$8:$R$47,MATCH(LARGE('Vendor Master'!$S$8:$S$47,3),'Vendor Master'!$S$8:$S$47,0))),"") -> C | F30: =IFERROR(INDEX('Invoice & Delivery Log'!$A$8:$A$157,MATCH(3,'Invoice & Delivery Log'!$Z$8:$Z$157,0)),"") -> INV-1010 | G30: =IFERROR(INDEX('Invoice & Delivery Log'!$C$8:$C$157,MATCH(3,'Invoice & Delivery Log'!$Z$8:$Z$157,0)),"") -> Copperfield Textiles | H30: =IFERROR(INDEX('Invoice & Delivery Log'!$M$8:$M$157,MATCH(3,'Invoice & Delivery Log'!$Z$8:$Z$157,0)),"") -> 46167 | I30: =IFERROR(INDEX('Invoice & Delivery Log'!$P$8:$P$157,MATCH(3,'Invoice & Delivery Log'!$Z$8:$Z$157,0)),"") -> 9042.96
A31: =IFERROR(IF(LARGE('Vendor Master'!$S$8:$S$47,4)<=0,"",INDEX('Vendor Master'!$B$8:$B$47,MATCH(LARGE('Vendor Master'!$S$8:$S$47,4),'Vendor Master'!$S$8:$S$47,0))),"") -> Lakeshore Packaging Group | B31: =IFERROR(IF(LARGE('Vendor Master'!$S$8:$S$47,4)<=0,"",INDEX('Vendor Master'!$L$8:$L$47,MATCH(LARGE('Vendor Master'!$S$8:$S$47,4),'Vendor Master'!$S$8:$S$47,0))),"") -> 6278.18 | C31: =IFERROR(IF(LARGE('Vendor Master'!$S$8:$S$47,4)<=0,"",INDEX('Vendor Master'!$M$8:$M$47,MATCH(LARGE('Vendor Master'!$S$8:$S$47,4),'Vendor Master'!$S$8:$S$47,0))),"") -> 1941.11 | D31: =IFERROR(IF(LARGE('Vendor Master'!$S$8:$S$47,4)<=0,"",INDEX('Vendor Master'!$R$8:$R$47,MATCH(LARGE('Vendor Master'!$S$8:$S$47,4),'Vendor Master'!$S$8:$S$47,0))),"") -> A | F31: =IFERROR(INDEX('Invoice & Delivery Log'!$A$8:$A$157,MATCH(4,'Invoice & Delivery Log'!$Z$8:$Z$157,0)),"") -> INV-1019 | G31: =IFERROR(INDEX('Invoice & Delivery Log'!$C$8:$C$157,MATCH(4,'Invoice & Delivery Log'!$Z$8:$Z$157,0)),"") -> Harborline Logistics | H31: =IFERROR(INDEX('Invoice & Delivery Log'!$M$8:$M$157,MATCH(4,'Invoice & Delivery Log'!$Z$8:$Z$157,0)),"") -> 46168 | I31: =IFERROR(INDEX('Invoice & Delivery Log'!$P$8:$P$157,MATCH(4,'Invoice & Delivery Log'!$Z$8:$Z$157,0)),"") -> 767.7
A32: =IFERROR(IF(LARGE('Vendor Master'!$S$8:$S$47,5)<=0,"",INDEX('Vendor Master'!$B$8:$B$47,MATCH(LARGE('Vendor Master'!$S$8:$S$47,5),'Vendor Master'!$S$8:$S$47,0))),"") -> Northwind Paper Supply | B32: =IFERROR(IF(LARGE('Vendor Master'!$S$8:$S$47,5)<=0,"",INDEX('Vendor Master'!$L$8:$L$47,MATCH(LARGE('Vendor Master'!$S$8:$S$47,5),'Vendor Master'!$S$8:$S$47,0))),"") -> 5176.74 | C32: =IFERROR(IF(LARGE('Vendor Master'!$S$8:$S$47,5)<=0,"",INDEX('Vendor Master'!$M$8:$M$47,MATCH(LARGE('Vendor Master'!$S$8:$S$47,5),'Vendor Master'!$S$8:$S$47,0))),"") -> 4090.42 | D32: =IFERROR(IF(LARGE('Vendor Master'!$S$8:$S$47,5)<=0,"",INDEX('Vendor Master'!$R$8:$R$47,MATCH(LARGE('Vendor Master'!$S$8:$S$47,5),'Vendor Master'!$S$8:$S$47,0))),"") -> B | F32: =IFERROR(INDEX('Invoice & Delivery Log'!$A$8:$A$157,MATCH(5,'Invoice & Delivery Log'!$Z$8:$Z$157,0)),"") -> INV-1024 | G32: =IFERROR(INDEX('Invoice & Delivery Log'!$C$8:$C$157,MATCH(5,'Invoice & Delivery Log'!$Z$8:$Z$157,0)),"") -> Ironbridge Hardware Co. | H32: =IFERROR(INDEX('Invoice & Delivery Log'!$M$8:$M$157,MATCH(5,'Invoice & Delivery Log'!$Z$8:$Z$157,0)),"") -> 46186 | I32: =IFERROR(INDEX('Invoice & Delivery Log'!$P$8:$P$157,MATCH(5,'Invoice & Delivery Log'!$Z$8:$Z$157,0)),"") -> 4198.12
A34: Monthly Invoiced vs Paid
A35: Month | B35: Invoiced | C35: Paid | D35: Net Movement
A36: 46082 | B36: =SUMIFS('Invoice & Delivery Log'!$N$8:$N$157,'Invoice & Delivery Log'!$H$8:$H$157,">="&$A36,'Invoice & Delivery Log'!$H$8:$H$157,"<="&EOMONTH($A36,0)) -> 49496.27 | C36: =SUMIFS('Payments Log'!$F$8:$F$207,'Payments Log'!$E$8:$E$207,">="&$A36,'Payments Log'!$E$8:$E$207,"<="&EOMONTH($A36,0)) -> 11300.96 | D36: =$B36-$C36 -> 38195.31
A37: 46113 | B37: =SUMIFS('Invoice & Delivery Log'!$N$8:$N$157,'Invoice & Delivery Log'!$H$8:$H$157,">="&$A37,'Invoice & Delivery Log'!$H$8:$H$157,"<="&EOMONTH($A37,0)) -> 43450.64 | C37: =SUMIFS('Payments Log'!$F$8:$F$207,'Payments Log'!$E$8:$E$207,">="&$A37,'Payments Log'!$E$8:$E$207,"<="&EOMONTH($A37,0)) -> 40062.55 | D37: =$B37-$C37 -> 3388.09
A38: 46143 | B38: =SUMIFS('Invoice & Delivery Log'!$N$8:$N$157,'Invoice & Delivery Log'!$H$8:$H$157,">="&$A38,'Invoice & Delivery Log'!$H$8:$H$157,"<="&EOMONTH($A38,0)) -> 33916.81 | C38: =SUMIFS('Payments Log'!$F$8:$F$207,'Payments Log'!$E$8:$E$207,">="&$A38,'Payments Log'!$E$8:$E$207,"<="&EOMONTH($A38,0)) -> 26867.57 | D38: =$B38-$C38 -> 7049.24
A39: 46174 | B39: =SUMIFS('Invoice & Delivery Log'!$N$8:$N$157,'Invoice & Delivery Log'!$H$8:$H$157,">="&$A39,'Invoice & Delivery Log'!$H$8:$H$157,"<="&EOMONTH($A39,0)) -> 29918.12 | C39: =SUMIFS('Payments Log'!$F$8:$F$207,'Payments Log'!$E$8:$E$207,">="&$A39,'Payments Log'!$E$8:$E$207,"<="&EOMONTH($A39,0)) -> 38431.19 | D39: =$B39-$C39 -> -8513.07
A40: 46204 | B40: =SUMIFS('Invoice & Delivery Log'!$N$8:$N$157,'Invoice & Delivery Log'!$H$8:$H$157,">="&$A40,'Invoice & Delivery Log'!$H$8:$H$157,"<="&EOMONTH($A40,0)) -> 23033.09 | C40: =SUMIFS('Payments Log'!$F$8:$F$207,'Payments Log'!$E$8:$E$207,">="&$A40,'Payments Log'!$E$8:$E$207,"<="&EOMONTH($A40,0)) -> 22048.71 | D40: =$B40-$C40 -> 984.38
A41: 46235 | B41: =SUMIFS('Invoice & Delivery Log'!$N$8:$N$157,'Invoice & Delivery Log'!$H$8:$H$157,">="&$A41,'Invoice & Delivery Log'!$H$8:$H$157,"<="&EOMONTH($A41,0)) -> 19263.63 | C41: =SUMIFS('Payments Log'!$F$8:$F$207,'Payments Log'!$E$8:$E$207,">="&$A41,'Payments Log'!$E$8:$E$207,"<="&EOMONTH($A41,0)) -> 11095.77 | D41: =$B41-$C41 -> 8167.86
A42: 46266 | B42: =SUMIFS('Invoice & Delivery Log'!$N$8:$N$157,'Invoice & Delivery Log'!$H$8:$H$157,">="&$A42,'Invoice & Delivery Log'!$H$8:$H$157,"<="&EOMONTH($A42,0)) -> 3330.15 | C42: =SUMIFS('Payments Log'!$F$8:$F$207,'Payments Log'!$E$8:$E$207,">="&$A42,'Payments Log'!$E$8:$E$207,"<="&EOMONTH($A42,0)) -> 838.24 | D42: =$B42-$C42 -> 2491.91
A43: Total | B43: =SUM($B$36:$B$42) -> 202408.71 | C43: =SUM($C$36:$C$42) -> 150644.99 | D43: =SUM($D$36:$D$42) -> 51763.72
A45: The monthly table counts invoices by invoice date and payments by payment date, so the two columns answer different questions: what we committed to, and what actually left the bank.

Sheet Vendor Master
A1: Vendor Master
A2: One row per supplier. Yellow columns are typed in; the rest is calculated from the invoice and payment logs.
A4: Vendor ID is the key that links this sheet to the Invoice & Delivery Log. Never reuse or renumber an ID.
A5: Supplier Score = On-Time Delivery Rate x weight (Settings!C14) + Full Receipt Rate x weight (Settings!C15). Rating bands are set in Settings rows 17-19.
A7: Vendor ID | B7: Vendor Name | C7: Category | D7: Contact Person | E7: Email | F7: Phone | G7: Payment Terms (Days) | H7: Vendor Status | I7: Invoices | J7: Total Invoiced | K7: Total Paid | L7: Outstanding Balance | M7: Overdue Amount | N7: On-Time Delivery Rate | O7: Full Receipt Rate | P7: Avg Days to Pay | Q7: Supplier Score | R7: Performance Rating | S7: Rank Key (helper)
A8: VEN-001 | B8: Northwind Paper Supply | C8: Office Supplies | D8: Dana Whitfield | E8: dana.whitfield@northwindpaper.example | F8: (312) 555-0142 | G8: 30 | H8: Active | I8: =IF($A8="","",COUNTIFS('Invoice & Delivery Log'!$B$8:$B$157,$A8)) -> 6 | J8: =IF($A8="","",SUMIFS('Invoice & Delivery Log'!$N$8:$N$157,'Invoice & Delivery Log'!$B$8:$B$157,$A8)) -> 8999.05 | K8: =IF($A8="","",SUMIFS('Invoice & Delivery Log'!$O$8:$O$157,'Invoice & Delivery Log'!$B$8:$B$157,$A8)) -> 3822.31 | L8: =IF($A8="","",SUMIFS('Invoice & Delivery Log'!$P$8:$P$157,'Invoice & Delivery Log'!$B$8:$B$157,$A8)) -> 5176.74 | M8: =IF($A8="","",SUMIFS('Invoice & Delivery Log'!$S$8:$S$157,'Invoice & Delivery Log'!$B$8:$B$157,$A8)) -> 4090.42 | N8: =IF($A8="","",IFERROR(COUNTIFS('Invoice & Delivery Log'!$B$8:$B$157,$A8,'Invoice & Delivery Log'!$V$8:$V$157,"On Time")/(COUNTIFS('Invoice & Delivery Log'!$B$8:$B$157,$A8,'Invoice & Delivery Log'!$V$8:$V$157,"On Time")+COUNTIFS('Invoice & Delivery Log'!$B$8:$B$157,$A8,'Invoice & Delivery Log'!$V$8:$V$157,"Late")),"")) -> 0.83333333 | O8: =IF($A8="","",IFERROR(COUNTIFS('Invoice & Delivery Log'!$B$8:$B$157,$A8,'Invoice & Delivery Log'!$K$8:$K$157,"Received in Full")/$I8,"")) -> 0.83333333 | P8: =IF($A8="","",IFERROR(ROUND(AVERAGEIFS('Payments Log'!$L$8:$L$207,'Payments Log'!$C$8:$C$207,$A8,'Payments Log'!$L$8:$L$207,">=0"),0),"")) -> 21 | Q8: =IF(OR($A8="",$I8=0),"",Settings!$C$14*IF($N8="",0,$N8)+Settings!$C$15*IF($O8="",0,$O8)) -> 0.83333333 | R8: =IF($Q8="","",IF($Q8>=Settings!$C$17,"A",IF($Q8>=Settings!$C$18,"B",IF($Q8>=Settings!$C$19,"C","D")))) -> B | S8: =IF($A8="","",$L8+ROW()/1000000) -> 5176.74
A9: VEN-002 | B9: Cascade Foods Distribution | C9: Food & Beverage | D9: Marco Ruiz | E9: marco.ruiz@cascadefoods.example | F9: (312) 555-0177 | G9: 15 | H9: Active | I9: =IF($A9="","",COUNTIFS('Invoice & Delivery Log'!$B$8:$B$157,$A9)) -> 6 | J9: =IF($A9="","",SUMIFS('Invoice & Delivery Log'!$N$8:$N$157,'Invoice & Delivery Log'!$B$8:$B$157,$A9)) -> 16224.28 | K9: =IF($A9="","",SUMIFS('Invoice & Delivery Log'!$O$8:$O$157,'Invoice & Delivery Log'!$B$8:$B$157,$A9)) -> 14304.51 | L9: =IF($A9="","",SUMIFS('Invoice & Delivery Log'!$P$8:$P$157,'Invoice & Delivery Log'!$B$8:$B$157,$A9)) -> 1919.77 | M9: =IF($A9="","",SUMIFS('Invoice & Delivery Log'!$S$8:$S$157,'Invoice & Delivery Log'!$B$8:$B$157,$A9)) -> 1919.77 | N9: =IF($A9="","",IFERROR(COUNTIFS('Invoice & Delivery Log'!$B$8:$B$157,$A9,'Invoice & Delivery Log'!$V$8:$V$157,"On Time")/(COUNTIFS('Invoice & Delivery Log'!$B$8:$B$157,$A9,'Invoice & Delivery Log'!$V$8:$V$157,"On Time")+COUNTIFS('Invoice & Delivery Log'!$B$8:$B$157,$A9,'Invoice & Delivery Log'!$V$8:$V$157,"Late")),"")) -> 0.83333333 | O9: =IF($A9="","",IFERROR(COUNTIFS('Invoice & Delivery Log'!$B$8:$B$157,$A9,'Invoice & Delivery Log'!$K$8:$K$157,"Received in Full")/$I9,"")) -> 0.5 | P9: =IF($A9="","",IFERROR(ROUND(AVERAGEIFS('Payments Log'!$L$8:$L$207,'Payments Log'!$C$8:$C$207,$A9,'Payments Log'!$L$8:$L$207,">=0"),0),"")) -> 10 | Q9: =IF(OR($A9="",$I9=0),"",Settings!$C$14*IF($N9="",0,$N9)+Settings!$C$15*IF($O9="",0,$O9)) -> 0.7 | R9: =IF($Q9="","",IF($Q9>=Settings!$C$17,"A",IF($Q9>=Settings!$C$18,"B",IF($Q9>=Settings!$C$19,"C","D")))) -> C | S9: =IF($A9="","",$L9+ROW()/1000000) -> 1919.77
A10: VEN-003 | B10: Ironbridge Hardware Co. | C10: Maintenance & Repair | D10: Priya Nadar | E10: priya.nadar@ironbridgehw.example | F10: (773) 555-0188 | G10: 45 | H10: Active | I10: =IF($A10="","",COUNTIFS('Invoice & Delivery Log'!$B$8:$B$157,$A10)) -> 5 | J10: =IF($A10="","",SUMIFS('Invoice & Delivery Log'!$N$8:$N$157,'Invoice & Delivery Log'!$B$8:$B$157,$A10)) -> 16426.14 | K10: =IF($A10="","",SUMIFS('Invoice & Delivery Log'!$O$8:$O$157,'Invoice & Delivery Log'!$B$8:$B$157,$A10)) -> 6023.58 | L10: =IF($A10="","",SUMIFS('Invoice & Delivery Log'!$P$8:$P$157,'Invoice & Delivery Log'!$B$8:$B$157,$A10)) -> 10402.56 | M10: =IF($A10="","",SUMIFS('Invoice & Delivery Log'!$S$8:$S$157,'Invoice & Delivery Log'!$B$8:$B$157,$A10)) -> 4198.12 | N10: =IF($A10="","",IFERROR(COUNTIFS('Invoice & Delivery Log'!$B$8:$B$157,$A10,'Invoice & Delivery Log'!$V$8:$V$157,"On Time")/(COUNTIFS('Invoice & Delivery Log'!$B$8:$B$157,$A10,'Invoice & Delivery Log'!$V$8:$V$157,"On Time")+COUNTIFS('Invoice & Delivery Log'!$B$8:$B$157,$A10,'Invoice & Delivery Log'!$V$8:$V$157,"Late")),"")) -> 0.6 | O10: =IF($A10="","",IFERROR(COUNTIFS('Invoice & Delivery Log'!$B$8:$B$157,$A10,'Invoice & Delivery Log'!$K$8:$K$157,"Received in Full")/$I10,"")) -> 1 | P10: =IF($A10="","",IFERROR(ROUND(AVERAGEIFS('Payments Log'!$L$8:$L$207,'Payments Log'!$C$8:$C$207,$A10,'Payments Log'!$L$8:$L$207,">=0"),0),"")) -> 8 | Q10: =IF(OR($A10="",$I10=0),"",Settings!$C$14*IF($N10="",0,$N10)+Settings!$C$15*IF($O10="",0,$O10)) -> 0.76 | R10: =IF($Q10="","",IF($Q10>=Settings!$C$17,"A",IF($Q10>=Settings!$C$18,"B",IF($Q10>=Settings!$C$19,"C","D")))) -> C | S10: =IF($A10="","",$L10+ROW()/1000000) -> 10402.56
A11: VEN-004 | B11: Lakeshore Packaging Group | C11: Packaging | D11: Ellen Novak | E11: ellen.novak@lakeshorepkg.example | F11: (847) 555-0113 | G11: 30 | H11: Active | I11: =IF($A11="","",COUNTIFS('Invoice & Delivery Log'!$B$8:$B$157,$A11)) -> 7 | J11: =IF($A11="","",SUMIFS('Invoice & Delivery Log'!$N$8:$N$157,'Invoice & Delivery Log'!$B$8:$B$157,$A11)) -> 28514.87 | K11: =IF($A11="","",SUMIFS('Invoice & Delivery Log'!$O$8:$O$157,'Invoice & Delivery Log'!$B$8:$B$157,$A11)) -> 22236.69 | L11: =IF($A11="","",SUMIFS('Invoice & Delivery Log'!$P$8:$P$157,'Invoice & Delivery Log'!$B$8:$B$157,$A11)) -> 6278.18 | M11: =IF($A11="","",SUMIFS('Invoice & Delivery Log'!$S$8:$S$157,'Invoice & Delivery Log'!$B$8:$B$157,$A11)) -> 1941.11 | N11: =IF($A11="","",IFERROR(COUNTIFS('Invoice & Delivery Log'!$B$8:$B$157,$A11,'Invoice & Delivery Log'!$V$8:$V$157,"On Time")/(COUNTIFS('Invoice & Delivery Log'!$B$8:$B$157,$A11,'Invoice & Delivery Log'!$V$8:$V$157,"On Time")+COUNTIFS('Invoice & Delivery Log'!$B$8:$B$157,$A11,'Invoice & Delivery Log'!$V$8:$V$157,"Late")),"")) -> 1 | O11: =IF($A11="","",IFERROR(COUNTIFS('Invoice & Delivery Log'!$B$8:$B$157,$A11,'Invoice & Delivery Log'!$K$8:$K$157,"Received in Full")/$I11,"")) -> 1 | P11: =IF($A11="","",IFERROR(ROUND(AVERAGEIFS('Payments Log'!$L$8:$L$207,'Payments Log'!$C$8:$C$207,$A11,'Payments Log'!$L$8:$L$207,">=0"),0),"")) -> 16 | Q11: =IF(OR($A11="",$I11=0),"",Settings!$C$14*IF($N11="",0,$N11)+Settings!$C$15*IF($O11="",0,$O11)) -> 1 | R11: =IF($Q11="","",IF($Q11>=Settings!$C$17,"A",IF($Q11>=Settings!$C$18,"B",IF($Q11>=Settings!$C$19,"C","D")))) -> A | S11: =IF($A11="","",$L11+ROW()/1000000) -> 6278.18
A12: VEN-005 | B12: Summit Cleaning Services | C12: Facility Services | D12: Tomas Berg | E12: tomas.berg@summitclean.example | F12: (224) 555-0166 | G12: 14 | H12: Active | I12: =IF($A12="","",COUNTIFS('Invoice & Delivery Log'!$B$8:$B$157,$A12)) -> 7 | J12: =IF($A12="","",SUMIFS('Invoice & Delivery Log'!$N$8:$N$157,'Invoice & Delivery Log'!$B$8:$B$157,$A12)) -> 11595.55 | K12: =IF($A12="","",SUMIFS('Invoice & Delivery Log'!$O$8:$O$157,'Invoice & Delivery Log'!$B$8:$B$157,$A12)) -> 11595.55 | L12: =IF($A12="","",SUMIFS('Invoice & Delivery Log'!$P$8:$P$157,'Invoice & Delivery Log'!$B$8:$B$157,$A12)) -> 0 | M12: =IF($A12="","",SUMIFS('Invoice & Delivery Log'!$S$8:$S$157,'Invoice & Delivery Log'!$B$8:$B$157,$A12)) -> 0 | N12: =IF($A12="","",IFERROR(COUNTIFS('Invoice & Delivery Log'!$B$8:$B$157,$A12,'Invoice & Delivery Log'!$V$8:$V$157,"On Time")/(COUNTIFS('Invoice & Delivery Log'!$B$8:$B$157,$A12,'Invoice & Delivery Log'!$V$8:$V$157,"On Time")+COUNTIFS('Invoice & Delivery Log'!$B$8:$B$157,$A12,'Invoice & Delivery Log'!$V$8:$V$157,"Late")),"")) -> 0.71428571 | O12: =IF($A12="","",IFERROR(COUNTIFS('Invoice & Delivery Log'!$B$8:$B$157,$A12,'Invoice & Delivery Log'!$K$8:$K$157,"Received in Full")/$I12,"")) -> 0.85714286 | P12: =IF($A12="","",IFERROR(ROUND(AVERAGEIFS('Payments Log'!$L$8:$L$207,'Payments Log'!$C$8:$C$207,$A12,'Payments Log'!$L$8:$L$207,">=0"),0),"")) -> 9 | Q12: =IF(OR($A12="",$I12=0),"",Settings!$C$14*IF($N12="",0,$N12)+Settings!$C$15*IF($O12="",0,$O12)) -> 0.77142857 | R12: =IF($Q12="","",IF($Q12>=Settings!$C$17,"A",IF($Q12>=Settings!$C$18,"B",IF($Q12>=Settings!$C$19,"C","D")))) -> C | S12: =IF($A12="","",$L12+ROW()/1000000) -> 1.2e-05
A13: VEN-006 | B13: Harborline Logistics | C13: Logistics | D13: Aisha Karim | E13: aisha.karim@harborlinelog.example | F13: (312) 555-0120 | G13: 30 | H13: Active | I13: =IF($A13="","",COUNTIFS('Invoice & Delivery Log'!$B$8:$B$157,$A13)) -> 10 | J13: =IF($A13="","",SUMIFS('Invoice & Delivery Log'!$N$8:$N$157,'Invoice & Delivery Log'!$B$8:$B$157,$A13)) -> 35790.13 | K13: =IF($A13="","",SUMIFS('Invoice & Delivery Log'!$O$8:$O$157,'Invoice & Delivery Log'!$B$8:$B$157,$A13)) -> 27898.6 | L13: =IF($A13="","",SUMIFS('Invoice & Delivery Log'!$P$8:$P$157,'Invoice & Delivery Log'!$B$8:$B$157,$A13)) -> 7891.53 | M13: =IF($A13="","",SUMIFS('Invoice & Delivery Log'!$S$8:$S$157,'Invoice & Delivery Log'!$B$8:$B$157,$A13)) -> 7891.53 | N13: =IF($A13="","",IFERROR(COUNTIFS('Invoice & Delivery Log'!$B$8:$B$157,$A13,'Invoice & Delivery Log'!$V$8:$V$157,"On Time")/(COUNTIFS('Invoice & Delivery Log'!$B$8:$B$157,$A13,'Invoice & Delivery Log'!$V$8:$V$157,"On Time")+COUNTIFS('Invoice & Delivery Log'!$B$8:$B$157,$A13,'Invoice & Delivery Log'!$V$8:$V$157,"Late")),"")) -> 0.6 | O13: =IF($A13="","",IFERROR(COUNTIFS('Invoice & Delivery Log'!$B$8:$B$157,$A13,'Invoice & Delivery Log'!$K$8:$K$157,"Received in Full")/$I13,"")) -> 0.9 | P13: =IF($A13="","",IFERROR(ROUND(AVERAGEIFS('Payments Log'!$L$8:$L$207,'Payments Log'!$C$8:$C$207,$A13,'Payments Log'!$L$8:$L$207,">=0"),0),"")) -> 22 | Q13: =IF(OR($A13="",$I13=0),"",Settings!$C$14*IF($N13="",0,$N13)+Settings!$C$15*IF($O13="",0,$O13)) -> 0.72 | R13: =IF($Q13="","",IF($Q13>=Settings!$C$17,"A",IF($Q13>=Settings!$C$18,"B",IF($Q13>=Settings!$C$19,"C","D")))) -> C | S13: =IF($A13="","",$L13+ROW()/1000000) -> 7891.53
A14: VEN-007 | B14: Bluepoint Electrical Supply | C14: Electrical | D14: Greg Salinas | E14: greg.salinas@bluepointel.example | F14: (630) 555-0195 | G14: 30 | H14: Active | I14: =IF($A14="","",COUNTIFS('Invoice & Delivery Log'!$B$8:$B$157,$A14)) -> 2 | J14: =IF($A14="","",SUMIFS('Invoice & Delivery Log'!$N$8:$N$157,'Invoice & Delivery Log'!$B$8:$B$157,$A14)) -> 3767.45 | K14: =IF($A14="","",SUMIFS('Invoice & Delivery Log'!$O$8:$O$157,'Invoice & Delivery Log'!$B$8:$B$157,$A14)) -> 3767.45 | L14: =IF($A14="","",SUMIFS('Invoice & Delivery Log'!$P$8:$P$157,'Invoice & Delivery Log'!$B$8:$B$157,$A14)) -> 0 | M14: =IF($A14="","",SUMIFS('Invoice & Delivery Log'!$S$8:$S$157,'Invoice & Delivery Log'!$B$8:$B$157,$A14)) -> 0 | N14: =IF($A14="","",IFERROR(COUNTIFS('Invoice & Delivery Log'!$B$8:$B$157,$A14,'Invoice & Delivery Log'!$V$8:$V$157,"On Time")/(COUNTIFS('Invoice & Delivery Log'!$B$8:$B$157,$A14,'Invoice & Delivery Log'!$V$8:$V$157,"On Time")+COUNTIFS('Invoice & Delivery Log'!$B$8:$B$157,$A14,'Invoice & Delivery Log'!$V$8:$V$157,"Late")),"")) -> 0.5 | O14: =IF($A14="","",IFERROR(COUNTIFS('Invoice & Delivery Log'!$B$8:$B$157,$A14,'Invoice & Delivery Log'!$K$8:$K$157,"Received in Full")/$I14,"")) -> 1 | P14: =IF($A14="","",IFERROR(ROUND(AVERAGEIFS('Payments Log'!$L$8:$L$207,'Payments Log'!$C$8:$C$207,$A14,'Payments Log'!$L$8:$L$207,">=0"),0),"")) -> 19 | Q14: =IF(OR($A14="",$I14=0),"",Settings!$C$14*IF($N14="",0,$N14)+Settings!$C$15*IF($O14="",0,$O14)) -> 0.7 | R14: =IF($Q14="","",IF($Q14>=Settings!$C$17,"A",IF($Q14>=Settings!$C$18,"B",IF($Q14>=Settings!$C$19,"C","D")))) -> C | S14: =IF($A14="","",$L14+ROW()/1000000) -> 1.4e-05
A15: VEN-008 | B15: Prairie Print & Signage | C15: Marketing & Print | D15: Nora Feldman | E15: nora.feldman@prairieprint.example | F15: (773) 555-0154 | G15: 21 | H15: Active | I15: =IF($A15="","",COUNTIFS('Invoice & Delivery Log'!$B$8:$B$157,$A15)) -> 1 | J15: =IF($A15="","",SUMIFS('Invoice & Delivery Log'!$N$8:$N$157,'Invoice & Delivery Log'!$B$8:$B$157,$A15)) -> 672.92 | K15: =IF($A15="","",SUMIFS('Invoice & Delivery Log'!$O$8:$O$157,'Invoice & Delivery Log'!$B$8:$B$157,$A15)) -> 672.92 | L15: =IF($A15="","",SUMIFS('Invoice & Delivery Log'!$P$8:$P$157,'Invoice & Delivery Log'!$B$8:$B$157,$A15)) -> 0 | M15: =IF($A15="","",SUMIFS('Invoice & Delivery Log'!$S$8:$S$157,'Invoice & Delivery Log'!$B$8:$B$157,$A15)) -> 0 | N15: =IF($A15="","",IFERROR(COUNTIFS('Invoice & Delivery Log'!$B$8:$B$157,$A15,'Invoice & Delivery Log'!$V$8:$V$157,"On Time")/(COUNTIFS('Invoice & Delivery Log'!$B$8:$B$157,$A15,'Invoice & Delivery Log'!$V$8:$V$157,"On Time")+COUNTIFS('Invoice & Delivery Log'!$B$8:$B$157,$A15,'Invoice & Delivery Log'!$V$8:$V$157,"Late")),"")) -> 1 | O15: =IF($A15="","",IFERROR(COUNTIFS('Invoice & Delivery Log'!$B$8:$B$157,$A15,'Invoice & Delivery Log'!$K$8:$K$157,"Received in Full")/$I15,"")) -> 1 | P15: =IF($A15="","",IFERROR(ROUND(AVERAGEIFS('Payments Log'!$L$8:$L$207,'Payments Log'!$C$8:$C$207,$A15,'Payments Log'!$L$8:$L$207,">=0"),0),"")) -> 8 | Q15: =IF(OR($A15="",$I15=0),"",Settings!$C$14*IF($N15="",0,$N15)+Settings!$C$15*IF($O15="",0,$O15)) -> 1 | R15: =IF($Q15="","",IF($Q15>=Settings!$C$17,"A",IF($Q15>=Settings!$C$18,"B",IF($Q15>=Settings!$C$19,"C","D")))) -> A | S15: =IF($A15="","",$L15+ROW()/1000000) -> 1.5e-05
A16: VEN-009 | B16: Vertex IT Solutions | C16: IT & Software | D16: Kevin Osei | E16: kevin.osei@vertexit.example | F16: (312) 555-0131 | G16: 30 | H16: Active | I16: =IF($A16="","",COUNTIFS('Invoice & Delivery Log'!$B$8:$B$157,$A16)) -> 5 | J16: =IF($A16="","",SUMIFS('Invoice & Delivery Log'!$N$8:$N$157,'Invoice & Delivery Log'!$B$8:$B$157,$A16)) -> 23638.56 | K16: =IF($A16="","",SUMIFS('Invoice & Delivery Log'!$O$8:$O$157,'Invoice & Delivery Log'!$B$8:$B$157,$A16)) -> 22773.69 | L16: =IF($A16="","",SUMIFS('Invoice & Delivery Log'!$P$8:$P$157,'Invoice & Delivery Log'!$B$8:$B$157,$A16)) -> 864.87 | M16: =IF($A16="","",SUMIFS('Invoice & Delivery Log'!$S$8:$S$157,'Invoice & Delivery Log'!$B$8:$B$157,$A16)) -> 864.87 | N16: =IF($A16="","",IFERROR(COUNTIFS('Invoice & Delivery Log'!$B$8:$B$157,$A16,'Invoice & Delivery Log'!$V$8:$V$157,"On Time")/(COUNTIFS('Invoice & Delivery Log'!$B$8:$B$157,$A16,'Invoice & Delivery Log'!$V$8:$V$157,"On Time")+COUNTIFS('Invoice & Delivery Log'!$B$8:$B$157,$A16,'Invoice & Delivery Log'!$V$8:$V$157,"Late")),"")) -> 1 | O16: =IF($A16="","",IFERROR(COUNTIFS('Invoice & Delivery Log'!$B$8:$B$157,$A16,'Invoice & Delivery Log'!$K$8:$K$157,"Received in Full")/$I16,"")) -> 1 | P16: =IF($A16="","",IFERROR(ROUND(AVERAGEIFS('Payments Log'!$L$8:$L$207,'Payments Log'!$C$8:$C$207,$A16,'Payments Log'!$L$8:$L$207,">=0"),0),"")) -> 20 | Q16: =IF(OR($A16="",$I16=0),"",Settings!$C$14*IF($N16="",0,$N16)+Settings!$C$15*IF($O16="",0,$O16)) -> 1 | R16: =IF($Q16="","",IF($Q16>=Settings!$C$17,"A",IF($Q16>=Settings!$C$18,"B",IF($Q16>=Settings!$C$19,"C","D")))) -> A | S16: =IF($A16="","",$L16+ROW()/1000000) -> 864.87002
A17: VEN-010 | B17: Copperfield Textiles | C17: Textiles | D17: Marta Silva | E17: marta.silva@copperfieldtex.example | F17: (847) 555-0109 | G17: 60 | H17: Active | I17: =IF($A17="","",COUNTIFS('Invoice & Delivery Log'!$B$8:$B$157,$A17)) -> 6 | J17: =IF($A17="","",SUMIFS('Invoice & Delivery Log'!$N$8:$N$157,'Invoice & Delivery Log'!$B$8:$B$157,$A17)) -> 47071.78 | K17: =IF($A17="","",SUMIFS('Invoice & Delivery Log'!$O$8:$O$157,'Invoice & Delivery Log'!$B$8:$B$157,$A17)) -> 29122.99 | L17: =IF($A17="","",SUMIFS('Invoice & Delivery Log'!$P$8:$P$157,'Invoice & Delivery Log'!$B$8:$B$157,$A17)) -> 17948.79 | M17: =IF($A17="","",SUMIFS('Invoice & Delivery Log'!$S$8:$S$157,'Invoice & Delivery Log'!$B$8:$B$157,$A17)) -> 9042.96 | N17: =IF($A17="","",IFERROR(COUNTIFS('Invoice & Delivery Log'!$B$8:$B$157,$A17,'Invoice & Delivery Log'!$V$8:$V$157,"On Time")/(COUNTIFS('Invoice & Delivery Log'!$B$8:$B$157,$A17,'Invoice & Delivery Log'!$V$8:$V$157,"On Time")+COUNTIFS('Invoice & Delivery Log'!$B$8:$B$157,$A17,'Invoice & Delivery Log'!$V$8:$V$157,"Late")),"")) -> 0.66666667 | O17: =IF($A17="","",IFERROR(COUNTIFS('Invoice & Delivery Log'!$B$8:$B$157,$A17,'Invoice & Delivery Log'!$K$8:$K$157,"Received in Full")/$I17,"")) -> 0.83333333 | P17: =IF($A17="","",IFERROR(ROUND(AVERAGEIFS('Payments Log'!$L$8:$L$207,'Payments Log'!$C$8:$C$207,$A17,'Payments Log'!$L$8:$L$207,">=0"),0),"")) -> 49 | Q17: =IF(OR($A17="",$I17=0),"",Settings!$C$14*IF($N17="",0,$N17)+Settings!$C$15*IF($O17="",0,$O17)) -> 0.73333333 | R17: =IF($Q17="","",IF($Q17>=Settings!$C$17,"A",IF($Q17>=Settings!$C$18,"B",IF($Q17>=Settings!$C$19,"C","D")))) -> C | S17: =IF($A17="","",$L17+ROW()/1000000) -> 17948.79
A18: VEN-011 | B18: Redstone Safety Equipment | C18: Safety & PPE | D18: Owen Brady | E18: owen.brady@redstonesafety.example | F18: (630) 555-0172 | G18: 30 | H18: Active | I18: =IF($A18="","",COUNTIFS('Invoice & Delivery Log'!$B$8:$B$157,$A18)) -> 2 | J18: =IF($A18="","",SUMIFS('Invoice & Delivery Log'!$N$8:$N$157,'Invoice & Delivery Log'!$B$8:$B$157,$A18)) -> 5653.27 | K18: =IF($A18="","",SUMIFS('Invoice & Delivery Log'!$O$8:$O$157,'Invoice & Delivery Log'!$B$8:$B$157,$A18)) -> 2891.99 | L18: =IF($A18="","",SUMIFS('Invoice & Delivery Log'!$P$8:$P$157,'Invoice & Delivery Log'!$B$8:$B$157,$A18)) -> 2761.28 | M18: =IF($A18="","",SUMIFS('Invoice & Delivery Log'!$S$8:$S$157,'Invoice & Delivery Log'!$B$8:$B$157,$A18)) -> 2761.28 | N18: =IF($A18="","",IFERROR(COUNTIFS('Invoice & Delivery Log'!$B$8:$B$157,$A18,'Invoice & Delivery Log'!$V$8:$V$157,"On Time")/(COUNTIFS('Invoice & Delivery Log'!$B$8:$B$157,$A18,'Invoice & Delivery Log'!$V$8:$V$157,"On Time")+COUNTIFS('Invoice & Delivery Log'!$B$8:$B$157,$A18,'Invoice & Delivery Log'!$V$8:$V$157,"Late")),"")) -> 1 | O18: =IF($A18="","",IFERROR(COUNTIFS('Invoice & Delivery Log'!$B$8:$B$157,$A18,'Invoice & Delivery Log'!$K$8:$K$157,"Received in Full")/$I18,"")) -> 1 | P18: =IF($A18="","",IFERROR(ROUND(AVERAGEIFS('Payments Log'!$L$8:$L$207,'Payments Log'!$C$8:$C$207,$A18,'Payments Log'!$L$8:$L$207,">=0"),0),"")) -> 13 | Q18: =IF(OR($A18="",$I18=0),"",Settings!$C$14*IF($N18="",0,$N18)+Settings!$C$15*IF($O18="",0,$O18)) -> 1 | R18: =IF($Q18="","",IF($Q18>=Settings!$C$17,"A",IF($Q18>=Settings!$C$18,"B",IF($Q18>=Settings!$C$19,"C","D")))) -> A | S18: =IF($A18="","",$L18+ROW()/1000000) -> 2761.28
A19: VEN-012 | B19: Willowbrook Beverage Co. | C19: Food & Beverage | D19: Lena Hart | E19: lena.hart@willowbrookbev.example | F19: (224) 555-0148 | G19: 15 | H19: Inactive | I19: =IF($A19="","",COUNTIFS('Invoice & Delivery Log'!$B$8:$B$157,$A19)) -> 3 | J19: =IF($A19="","",SUMIFS('Invoice & Delivery Log'!$N$8:$N$157,'Invoice & Delivery Log'!$B$8:$B$157,$A19)) -> 4054.71 | K19: =IF($A19="","",SUMIFS('Invoice & Delivery Log'!$O$8:$O$157,'Invoice & Delivery Log'!$B$8:$B$157,$A19)) -> 4054.71 | L19: =IF($A19="","",SUMIFS('Invoice & Delivery Log'!$P$8:$P$157,'Invoice & Delivery Log'!$B$8:$B$157,$A19)) -> 0 | M19: =IF($A19="","",SUMIFS('Invoice & Delivery Log'!$S$8:$S$157,'Invoice & Delivery Log'!$B$8:$B$157,$A19)) -> 0 | N19: =IF($A19="","",IFERROR(COUNTIFS('Invoice & Delivery Log'!$B$8:$B$157,$A19,'Invoice & Delivery Log'!$V$8:$V$157,"On Time")/(COUNTIFS('Invoice & Delivery Log'!$B$8:$B$157,$A19,'Invoice & Delivery Log'!$V$8:$V$157,"On Time")+COUNTIFS('Invoice & Delivery Log'!$B$8:$B$157,$A19,'Invoice & Delivery Log'!$V$8:$V$157,"Late")),"")) -> 1 | O19: =IF($A19="","",IFERROR(COUNTIFS('Invoice & Delivery Log'!$B$8:$B$157,$A19,'Invoice & Delivery Log'!$K$8:$K$157,"Received in Full")/$I19,"")) -> 1 | P19: =IF($A19="","",IFERROR(ROUND(AVERAGEIFS('Payments Log'!$L$8:$L$207,'Payments Log'!$C$8:$C$207,$A19,'Payments Log'!$L$8:$L$207,">=0"),0),"")) -> 15 | Q19: =IF(OR($A19="",$I19=0),"",Settings!$C$14*IF($N19="",0,$N19)+Settings!$C$15*IF($O19="",0,$O19)) -> 1 | R19: =IF($Q19="","",IF($Q19>=Settings!$C$17,"A",IF($Q19>=Settings!$C$18,"B",IF($Q19>=Settings!$C$19,"C","D")))) -> A | S19: =IF($A19="","",$L19+ROW()/1000000) -> 1.9e-05
I20: =IF($A20="","",COUNTIFS('Invoice & Delivery Log'!$B$8:$B$157,$A20)) | J20: =IF($A20="","",SUMIFS('Invoice & Delivery Log'!$N$8:$N$157,'Invoice & Delivery Log'!$B$8:$B$157,$A20)) | K20: =IF($A20="","",SUMIFS('Invoice & Delivery Log'!$O$8:$O$157,'Invoice & Delivery Log'!$B$8:$B$157,$A20)) | L20: =IF($A20="","",SUMIFS('Invoice & Delivery Log'!$P$8:$P$157,'Invoice & Delivery Log'!$B$8:$B$157,$A20)) | M20: =IF($A20="","",SUMIFS('Invoice & Delivery Log'!$S$8:$S$157,'Invoice & Delivery Log'!$B$8:$B$157,$A20)) | N20: =IF($A20="","",IFERROR(COUNTIFS('Invoice & Delivery Log'!$B$8:$B$157,$A20,'Invoice & Delivery Log'!$V$8:$V$157,"On Time")/(COUNTIFS('Invoice & Delivery Log'!$B$8:$B$157,$A20,'Invoice & Delivery Log'!$V$8:$V$157,"On Time")+COUNTIFS('Invoice & Delivery Log'!$B$8:$B$157,$A20,'Invoice & Delivery Log'!$V$8:$V$157,"Late")),"")) | O20: =IF($A20="","",IFERROR(COUNTIFS('Invoice & Delivery Log'!$B$8:$B$157,$A20,'Invoice & Delivery Log'!$K$8:$K$157,"Received in Full")/$I20,"")) | P20: =IF($A20="","",IFERROR(ROUND(AVERAGEIFS('Payments Log'!$L$8:$L$207,'Payments Log'!$C$8:$C$207,$A20,'Payments Log'!$L$8:$L$207,">=0"),0),"")) | Q20: =IF(OR($A20="",$I20=0),"",Settings!$C$14*IF($N20="",0,$N20)+Settings!$C$15*IF($O20="",0,$O20)) | R20: =IF($Q20="","",IF($Q20>=Settings!$C$17,"A",IF($Q20>=Settings!$C$18,"B",IF($Q20>=Settings!$C$19,"C","D")))) | S20: =IF($A20="","",$L20+ROW()/1000000)
I21: =IF($A21="","",COUNTIFS('Invoice & Delivery Log'!$B$8:$B$157,$A21)) | J21: =IF($A21="","",SUMIFS('Invoice & Delivery Log'!$N$8:$N$157,'Invoice & Delivery Log'!$B$8:$B$157,$A21)) | K21: =IF($A21="","",SUMIFS('Invoice & Delivery Log'!$O$8:$O$157,'Invoice & Delivery Log'!$B$8:$B$157,$A21)) | L21: =IF($A21="","",SUMIFS('Invoice & Delivery Log'!$P$8:$P$157,'Invoice & Delivery Log'!$B$8:$B$157,$A21)) | M21: =IF($A21="","",SUMIFS('Invoice & Delivery Log'!$S$8:$S$157,'Invoice & Delivery Log'!$B$8:$B$157,$A21)) | N21: =IF($A21="","",IFERROR(COUNTIFS('Invoice & Delivery Log'!$B$8:$B$157,$A21,'Invoice & Delivery Log'!$V$8:$V$157,"On Time")/(COUNTIFS('Invoice & Delivery Log'!$B$8:$B$157,$A21,'Invoice & Delivery Log'!$V$8:$V$157,"On Time")+COUNTIFS('Invoice & Delivery Log'!$B$8:$B$157,$A21,'Invoice & Delivery Log'!$V$8:$V$157,"Late")),"")) | O21: =IF($A21="","",IFERROR(COUNTIFS('Invoice & Delivery Log'!$B$8:$B$157,$A21,'Invoice & Delivery Log'!$K$8:$K$157,"Received in Full")/$I21,"")) | P21: =IF($A21="","",IFERROR(ROUND(AVERAGEIFS('Payments Log'!$L$8:$L$207,'Payments Log'!$C$8:$C$207,$A21,'Payments Log'!$L$8:$L$207,">=0"),0),"")) | Q21: =IF(OR($A21="",$I21=0),"",Settings!$C$14*IF($N21="",0,$N21)+Settings!$C$15*IF($O21="",0,$O21)) | R21: =IF($Q21="","",IF($Q21>=Settings!$C$17,"A",IF($Q21>=Settings!$C$18,"B",IF($Q21>=Settings!$C$19,"C","D")))) | S21: =IF($A21="","",$L21+ROW()/1000000)
I22: =IF($A22="","",COUNTIFS('Invoice & Delivery Log'!$B$8:$B$157,$A22)) | J22: =IF($A22="","",SUMIFS('Invoice & Delivery Log'!$N$8:$N$157,'Invoice & Delivery Log'!$B$8:$B$157,$A22)) | K22: =IF($A22="","",SUMIFS('Invoice & Delivery Log'!$O$8:$O$157,'Invoice & Delivery Log'!$B$8:$B$157,$A22)) | L22: =IF($A22="","",SUMIFS('Invoice & Delivery Log'!$P$8:$P$157,'Invoice & Delivery Log'!$B$8:$B$157,$A22)) | M22: =IF($A22="","",SUMIFS('Invoice & Delivery Log'!$S$8:$S$157,'Invoice & Delivery Log'!$B$8:$B$157,$A22)) | N22: =IF($A22="","",IFERROR(COUNTIFS('Invoice & Delivery Log'!$B$8:$B$157,$A22,'Invoice & Delivery Log'!$V$8:$V$157,"On Time")/(COUNTIFS('Invoice & Delivery Log'!$B$8:$B$157,$A22,'Invoice & Delivery Log'!$V$8:$V$157,"On Time")+COUNTIFS('Invoice & Delivery Log'!$B$8:$B$157,$A22,'Invoice & Delivery Log'!$V$8:$V$157,"Late")),"")) | O22: =IF($A22="","",IFERROR(COUNTIFS('Invoice & Delivery Log'!$B$8:$B$157,$A22,'Invoice & Delivery Log'!$K$8:$K$157,"Received in Full")/$I22,"")) | P22: =IF($A22="","",IFERROR(ROUND(AVERAGEIFS('Payments Log'!$L$8:$L$207,'Payments Log'!$C$8:$C$207,$A22,'Payments Log'!$L$8:$L$207,">=0"),0),"")) | Q22: =IF(OR($A22="",$I22=0),"",Settings!$C$14*IF($N22="",0,$N22)+Settings!$C$15*IF($O22="",0,$O22)) | R22: =IF($Q22="","",IF($Q22>=Settings!$C$17,"A",IF($Q22>=Settings!$C$18,"B",IF($Q22>=Settings!$C$19,"C","D")))) | S22: =IF($A22="","",$L22+ROW()/1000000)
I23: =IF($A23="","",COUNTIFS('Invoice & Delivery Log'!$B$8:$B$157,$A23)) | J23: =IF($A23="","",SUMIFS('Invoice & Delivery Log'!$N$8:$N$157,'Invoice & Delivery Log'!$B$8:$B$157,$A23)) | K23: =IF($A23="","",SUMIFS('Invoice & Delivery Log'!$O$8:$O$157,'Invoice & Delivery Log'!$B$8:$B$157,$A23)) | L23: =IF($A23="","",SUMIFS('Invoice & Delivery Log'!$P$8:$P$157,'Invoice & Delivery Log'!$B$8:$B$157,$A23)) | M23: =IF($A23="","",SUMIFS('Invoice & Delivery Log'!$S$8:$S$157,'Invoice & Delivery Log'!$B$8:$B$157,$A23)) | N23: =IF($A23="","",IFERROR(COUNTIFS('Invoice & Delivery Log'!$B$8:$B$157,$A23,'Invoice & Delivery Log'!$V$8:$V$157,"On Time")/(COUNTIFS('Invoice & Delivery Log'!$B$8:$B$157,$A23,'Invoice & Delivery Log'!$V$8:$V$157,"On Time")+COUNTIFS('Invoice & Delivery Log'!$B$8:$B$157,$A23,'Invoice & Delivery Log'!$V$8:$V$157,"Late")),"")) | O23: =IF($A23="","",IFERROR(COUNTIFS('Invoice & Delivery Log'!$B$8:$B$157,$A23,'Invoice & Delivery Log'!$K$8:$K$157,"Received in Full")/$I23,"")) | P23: =IF($A23="","",IFERROR(ROUND(AVERAGEIFS('Payments Log'!$L$8:$L$207,'Payments Log'!$C$8:$C$207,$A23,'Payments Log'!$L$8:$L$207,">=0"),0),"")) | Q23: =IF(OR($A23="",$I23=0),"",Settings!$C$14*IF($N23="",0,$N23)+Settings!$C$15*IF($O23="",0,$O23)) | R23: =IF($Q23="","",IF($Q23>=Settings!$C$17,"A",IF($Q23>=Settings!$C$18,"B",IF($Q23>=Settings!$C$19,"C","D")))) | S23: =IF($A23="","",$L23+ROW()/1000000)
I24: =IF($A24="","",COUNTIFS('Invoice & Delivery Log'!$B$8:$B$157,$A24)) | J24: =IF($A24="","",SUMIFS('Invoice & Delivery Log'!$N$8:$N$157,'Invoice & Delivery Log'!$B$8:$B$157,$A24)) | K24: =IF($A24="","",SUMIFS('Invoice & Delivery Log'!$O$8:$O$157,'Invoice & Delivery Log'!$B$8:$B$157,$A24)) | L24: =IF($A24="","",SUMIFS('Invoice & Delivery Log'!$P$8:$P$157,'Invoice & Delivery Log'!$B$8:$B$157,$A24)) | M24: =IF($A24="","",SUMIFS('Invoice & Delivery Log'!$S$8:$S$157,'Invoice & Delivery Log'!$B$8:$B$157,$A24)) | N24: =IF($A24="","",IFERROR(COUNTIFS('Invoice & Delivery Log'!$B$8:$B$157,$A24,'Invoice & Delivery Log'!$V$8:$V$157,"On Time")/(COUNTIFS('Invoice & Delivery Log'!$B$8:$B$157,$A24,'Invoice & Delivery Log'!$V$8:$V$157,"On Time")+COUNTIFS('Invoice & Delivery Log'!$B$8:$B$157,$A24,'Invoice & Delivery Log'!$V$8:$V$157,"Late")),"")) | O24: =IF($A24="","",IFERROR(COUNTIFS('Invoice & Delivery Log'!$B$8:$B$157,$A24,'Invoice & Delivery Log'!$K$8:$K$157,"Received in Full")/$I24,"")) | P24: =IF($A24="","",IFERROR(ROUND(AVERAGEIFS('Payments Log'!$L$8:$L$207,'Payments Log'!$C$8:$C$207,$A24,'Payments Log'!$L$8:$L$207,">=0"),0),"")) | Q24: =IF(OR($A24="",$I24=0),"",Settings!$C$14*IF($N24="",0,$N24)+Settings!$C$15*IF($O24="",0,$O24)) | R24: =IF($Q24="","",IF($Q24>=Settings!$C$17,"A",IF($Q24>=Settings!$C$18,"B",IF($Q24>=Settings!$C$19,"C","D")))) | S24: =IF($A24="","",$L24+ROW()/1000000)
I25: =IF($A25="","",COUNTIFS('Invoice & Delivery Log'!$B$8:$B$157,$A25)) | J25: =IF($A25="","",SUMIFS('Invoice & Delivery Log'!$N$8:$N$157,'Invoice & Delivery Log'!$B$8:$B$157,$A25)) | K25: =IF($A25="","",SUMIFS('Invoice & Delivery Log'!$O$8:$O$157,'Invoice & Delivery Log'!$B$8:$B$157,$A25)) | L25: =IF($A25="","",SUMIFS('Invoice & Delivery Log'!$P$8:$P$157,'Invoice & Delivery Log'!$B$8:$B$157,$A25)) | M25: =IF($A25="","",SUMIFS('Invoice & Delivery Log'!$S$8:$S$157,'Invoice & Delivery Log'!$B$8:$B$157,$A25)) | N25: =IF($A25="","",IFERROR(COUNTIFS('Invoice & Delivery Log'!$B$8:$B$157,$A25,'Invoice & Delivery Log'!$V$8:$V$157,"On Time")/(COUNTIFS('Invoice & Delivery Log'!$B$8:$B$157,$A25,'Invoice & Delivery Log'!$V$8:$V$157,"On Time")+COUNTIFS('Invoice & Delivery Log'!$B$8:$B$157,$A25,'Invoice & Delivery Log'!$V$8:$V$157,"Late")),"")) | O25: =IF($A25="","",IFERROR(COUNTIFS('Invoice & Delivery Log'!$B$8:$B$157,$A25,'Invoice & Delivery Log'!$K$8:$K$157,"Received in Full")/$I25,"")) | P25: =IF($A25="","",IFERROR(ROUND(AVERAGEIFS('Payments Log'!$L$8:$L$207,'Payments Log'!$C$8:$C$207,$A25,'Payments Log'!$L$8:$L$207,">=0"),0),"")) | Q25: =IF(OR($A25="",$I25=0),"",Settings!$C$14*IF($N25="",0,$N25)+Settings!$C$15*IF($O25="",0,$O25)) | R25: =IF($Q25="","",IF($Q25>=Settings!$C$17,"A",IF($Q25>=Settings!$C$18,"B",IF($Q25>=Settings!$C$19,"C","D")))) | S25: =IF($A25="","",$L25+ROW()/1000000)
I26: =IF($A26="","",COUNTIFS('Invoice & Delivery Log'!$B$8:$B$157,$A26)) | J26: =IF($A26="","",SUMIFS('Invoice & Delivery Log'!$N$8:$N$157,'Invoice & Delivery Log'!$B$8:$B$157,$A26)) | K26: =IF($A26="","",SUMIFS('Invoice & Delivery Log'!$O$8:$O$157,'Invoice & Delivery Log'!$B$8:$B$157,$A26)) | L26: =IF($A26="","",SUMIFS('Invoice & Delivery Log'!$P$8:$P$157,'Invoice & Delivery Log'!$B$8:$B$157,$A26)) | M26: =IF($A26="","",SUMIFS('Invoice & Delivery Log'!$S$8:$S$157,'Invoice & Delivery Log'!$B$8:$B$157,$A26)) | N26: =IF($A26="","",IFERROR(COUNTIFS('Invoice & Delivery Log'!$B$8:$B$157,$A26,'Invoice & Delivery Log'!$V$8:$V$157,"On Time")/(COUNTIFS('Invoice & Delivery Log'!$B$8:$B$157,$A26,'Invoice & Delivery Log'!$V$8:$V$157,"On Time")+COUNTIFS('Invoice & Delivery Log'!$B$8:$B$157,$A26,'Invoice & Delivery Log'!$V$8:$V$157,"Late")),"")) | O26: =IF($A26="","",IFERROR(COUNTIFS('Invoice & Delivery Log'!$B$8:$B$157,$A26,'Invoice & Delivery Log'!$K$8:$K$157,"Received in Full")/$I26,"")) | P26: =IF($A26="","",IFERROR(ROUND(AVERAGEIFS('Payments Log'!$L$8:$L$207,'Payments Log'!$C$8:$C$207,$A26,'Payments Log'!$L$8:$L$207,">=0"),0),"")) | Q26: =IF(OR($A26="",$I26=0),"",Settings!$C$14*IF($N26="",0,$N26)+Settings!$C$15*IF($O26="",0,$O26)) | R26: =IF($Q26="","",IF($Q26>=Settings!$C$17,"A",IF($Q26>=Settings!$C$18,"B",IF($Q26>=Settings!$C$19,"C","D")))) | S26: =IF($A26="","",$L26+ROW()/1000000)
I27: =IF($A27="","",COUNTIFS('Invoice & Delivery Log'!$B$8:$B$157,$A27)) | J27: =IF($A27="","",SUMIFS('Invoice & Delivery Log'!$N$8:$N$157,'Invoice & Delivery Log'!$B$8:$B$157,$A27)) | K27: =IF($A27="","",SUMIFS('Invoice & Delivery Log'!$O$8:$O$157,'Invoice & Delivery Log'!$B$8:$B$157,$A27)) | L27: =IF($A27="","",SUMIFS('Invoice & Delivery Log'!$P$8:$P$157,'Invoice & Delivery Log'!$B$8:$B$157,$A27)) | M27: =IF($A27="","",SUMIFS('Invoice & Delivery Log'!$S$8:$S$157,'Invoice & Delivery Log'!$B$8:$B$157,$A27)) | N27: =IF($A27="","",IFERROR(COUNTIFS('Invoice & Delivery Log'!$B$8:$B$157,$A27,'Invoice & Delivery Log'!$V$8:$V$157,"On Time")/(COUNTIFS('Invoice & Delivery Log'!$B$8:$B$157,$A27,'Invoice & Delivery Log'!$V$8:$V$157,"On Time")+COUNTIFS('Invoice & Delivery Log'!$B$8:$B$157,$A27,'Invoice & Delivery Log'!$V$8:$V$157,"Late")),"")) | O27: =IF($A27="","",IFERROR(COUNTIFS('Invoice & Delivery Log'!$B$8:$B$157,$A27,'Invoice & Delivery Log'!$K$8:$K$157,"Received in Full")/$I27,"")) | P27: =IF($A27="","",IFERROR(ROUND(AVERAGEIFS('Payments Log'!$L$8:$L$207,'Payments Log'!$C$8:$C$207,$A27,'Payments Log'!$L$8:$L$207,">=0"),0),"")) | Q27: =IF(OR($A27="",$I27=0),"",Settings!$C$14*IF($N27="",0,$N27)+Settings!$C$15*IF($O27="",0,$O27)) | R27: =IF($Q27="","",IF($Q27>=Settings!$C$17,"A",IF($Q27>=Settings!$C$18,"B",IF($Q27>=Settings!$C$19,"C","D")))) | S27: =IF($A27="","",$L27+ROW()/1000000)
I28: =IF($A28="","",COUNTIFS('Invoice & Delivery Log'!$B$8:$B$157,$A28)) | J28: =IF($A28="","",SUMIFS('Invoice & Delivery Log'!$N$8:$N$157,'Invoice & Delivery Log'!$B$8:$B$157,$A28)) | K28: =IF($A28="","",SUMIFS('Invoice & Delivery Log'!$O$8:$O$157,'Invoice & Delivery Log'!$B$8:$B$157,$A28)) | L28: =IF($A28="","",SUMIFS('Invoice & Delivery Log'!$P$8:$P$157,'Invoice & Delivery Log'!$B$8:$B$157,$A28)) | M28: =IF($A28="","",SUMIFS('Invoice & Delivery Log'!$S$8:$S$157,'Invoice & Delivery Log'!$B$8:$B$157,$A28)) | N28: =IF($A28="","",IFERROR(COUNTIFS('Invoice & Delivery Log'!$B$8:$B$157,$A28,'Invoice & Delivery Log'!$V$8:$V$157,"On Time")/(COUNTIFS('Invoice & Delivery Log'!$B$8:$B$157,$A28,'Invoice & Delivery Log'!$V$8:$V$157,"On Time")+COUNTIFS('Invoice & Delivery Log'!$B$8:$B$157,$A28,'Invoice & Delivery Log'!$V$8:$V$157,"Late")),"")) | O28: =IF($A28="","",IFERROR(COUNTIFS('Invoice & Delivery Log'!$B$8:$B$157,$A28,'Invoice & Delivery Log'!$K$8:$K$157,"Received in Full")/$I28,"")) | P28: =IF($A28="","",IFERROR(ROUND(AVERAGEIFS('Payments Log'!$L$8:$L$207,'Payments Log'!$C$8:$C$207,$A28,'Payments Log'!$L$8:$L$207,">=0"),0),"")) | Q28: =IF(OR($A28="",$I28=0),"",Settings!$C$14*IF($N28="",0,$N28)+Settings!$C$15*IF($O28="",0,$O28)) | R28: =IF($Q28="","",IF($Q28>=Settings!$C$17,"A",IF($Q28>=Settings!$C$18,"B",IF($Q28>=Settings!$C$19,"C","D")))) | S28: =IF($A28="","",$L28+ROW()/1000000)
I29: =IF($A29="","",COUNTIFS('Invoice & Delivery Log'!$B$8:$B$157,$A29)) | J29: =IF($A29="","",SUMIFS('Invoice & Delivery Log'!$N$8:$N$157,'Invoice & Delivery Log'!$B$8:$B$157,$A29)) | K29: =IF($A29="","",SUMIFS('Invoice & Delivery Log'!$O$8:$O$157,'Invoice & Delivery Log'!$B$8:$B$157,$A29)) | L29: =IF($A29="","",SUMIFS('Invoice & Delivery Log'!$P$8:$P$157,'Invoice & Delivery Log'!$B$8:$B$157,$A29)) | M29: =IF($A29="","",SUMIFS('Invoice & Delivery Log'!$S$8:$S$157,'Invoice & Delivery Log'!$B$8:$B$157,$A29)) | N29: =IF($A29="","",IFERROR(COUNTIFS('Invoice & Delivery Log'!$B$8:$B$157,$A29,'Invoice & Delivery Log'!$V$8:$V$157,"On Time")/(COUNTIFS('Invoice & Delivery Log'!$B$8:$B$157,$A29,'Invoice & Delivery Log'!$V$8:$V$157,"On Time")+COUNTIFS('Invoice & Delivery Log'!$B$8:$B$157,$A29,'Invoice & Delivery Log'!$V$8:$V$157,"Late")),"")) | O29: =IF($A29="","",IFERROR(COUNTIFS('Invoice & Delivery Log'!$B$8:$B$157,$A29,'Invoice & Delivery Log'!$K$8:$K$157,"Received in Full")/$I29,"")) | P29: =IF($A29="","",IFERROR(ROUND(AVERAGEIFS('Payments Log'!$L$8:$L$207,'Payments Log'!$C$8:$C$207,$A29,'Payments Log'!$L$8:$L$207,">=0"),0),"")) | Q29: =IF(OR($A29="",$I29=0),"",Settings!$C$14*IF($N29="",0,$N29)+Settings!$C$15*IF($O29="",0,$O29)) | R29: =IF($Q29="","",IF($Q29>=Settings!$C$17,"A",IF($Q29>=Settings!$C$18,"B",IF($Q29>=Settings!$C$19,"C","D")))) | S29: =IF($A29="","",$L29+ROW()/1000000)
I30: =IF($A30="","",COUNTIFS('Invoice & Delivery Log'!$B$8:$B$157,$A30)) | J30: =IF($A30="","",SUMIFS('Invoice & Delivery Log'!$N$8:$N$157,'Invoice & Delivery Log'!$B$8:$B$157,$A30)) | K30: =IF($A30="","",SUMIFS('Invoice & Delivery Log'!$O$8:$O$157,'Invoice & Delivery Log'!$B$8:$B$157,$A30)) | L30: =IF($A30="","",SUMIFS('Invoice & Delivery Log'!$P$8:$P$157,'Invoice & Delivery Log'!$B$8:$B$157,$A30)) | M30: =IF($A30="","",SUMIFS('Invoice & Delivery Log'!$S$8:$S$157,'Invoice & Delivery Log'!$B$8:$B$157,$A30)) | N30: =IF($A30="","",IFERROR(COUNTIFS('Invoice & Delivery Log'!$B$8:$B$157,$A30,'Invoice & Delivery Log'!$V$8:$V$157,"On Time")/(COUNTIFS('Invoice & Delivery Log'!$B$8:$B$157,$A30,'Invoice & Delivery Log'!$V$8:$V$157,"On Time")+COUNTIFS('Invoice & Delivery Log'!$B$8:$B$157,$A30,'Invoice & Delivery Log'!$V$8:$V$157,"Late")),"")) | O30: =IF($A30="","",IFERROR(COUNTIFS('Invoice & Delivery Log'!$B$8:$B$157,$A30,'Invoice & Delivery Log'!$K$8:$K$157,"Received in Full")/$I30,"")) | P30: =IF($A30="","",IFERROR(ROUND(AVERAGEIFS('Payments Log'!$L$8:$L$207,'Payments Log'!$C$8:$C$207,$A30,'Payments Log'!$L$8:$L$207,">=0"),0),"")) | Q30: =IF(OR($A30="",$I30=0),"",Settings!$C$14*IF($N30="",0,$N30)+Settings!$C$15*IF($O30="",0,$O30)) | R30: =IF($Q30="","",IF($Q30>=Settings!$C$17,"A",IF($Q30>=Settings!$C$18,"B",IF($Q30>=Settings!$C$19,"C","D")))) | S30: =IF($A30="","",$L30+ROW()/1000000)
I31: =IF($A31="","",COUNTIFS('Invoice & Delivery Log'!$B$8:$B$157,$A31)) | J31: =IF($A31="","",SUMIFS('Invoice & Delivery Log'!$N$8:$N$157,'Invoice & Delivery Log'!$B$8:$B$157,$A31)) | K31: =IF($A31="","",SUMIFS('Invoice & Delivery Log'!$O$8:$O$157,'Invoice & Delivery Log'!$B$8:$B$157,$A31)) | L31: =IF($A31="","",SUMIFS('Invoice & Delivery Log'!$P$8:$P$157,'Invoice & Delivery Log'!$B$8:$B$157,$A31)) | M31: =IF($A31="","",SUMIFS('Invoice & Delivery Log'!$S$8:$S$157,'Invoice & Delivery Log'!$B$8:$B$157,$A31)) | N31: =IF($A31="","",IFERROR(COUNTIFS('Invoice & Delivery Log'!$B$8:$B$157,$A31,'Invoice & Delivery Log'!$V$8:$V$157,"On Time")/(COUNTIFS('Invoice & Delivery Log'!$B$8:$B$157,$A31,'Invoice & Delivery Log'!$V$8:$V$157,"On Time")+COUNTIFS('Invoice & Delivery Log'!$B$8:$B$157,$A31,'Invoice & Delivery Log'!$V$8:$V$157,"Late")),"")) | O31: =IF($A31="","",IFERROR(COUNTIFS('Invoice & Delivery Log'!$B$8:$B$157,$A31,'Invoice & Delivery Log'!$K$8:$K$157,"Received in Full")/$I31,"")) | P31: =IF($A31="","",IFERROR(ROUND(AVERAGEIFS('Payments Log'!$L$8:$L$207,'Payments Log'!$C$8:$C$207,$A31,'Payments Log'!$L$8:$L$207,">=0"),0),"")) | Q31: =IF(OR($A31="",$I31=0),"",Settings!$C$14*IF($N31="",0,$N31)+Settings!$C$15*IF($O31="",0,$O31)) | R31: =IF($Q31="","",IF($Q31>=Settings!$C$17,"A",IF($Q31>=Settings!$C$18,"B",IF($Q31>=Settings!$C$19,"C","D")))) | S31: =IF($A31="","",$L31+ROW()/1000000)
... I47: =IF($A47="","",COUNTIFS('Invoice & Delivery Log'!$B$8:$B$157,$A47)) | J47: =IF($A47="","",SUMIFS('Invoice & Delivery Log'!$N$8:$N$157,'Invoice & Delivery Log'!$B$8:$B$157,$A47)) | K47: =IF($A47="","",SUMIFS('Invoice & Delivery Log'!$O$8:$O$157,'Invoice & Delivery Log'!$B$8:$B$157,$A47)) | L47: =IF($A47="","",SUMIFS('Invoice & Delivery Log'!$P$8:$P$157,'Invoice & Delivery Log'!$B$8:$B$157,$A47)) | M47: =IF($A47="","",SUMIFS('Invoice & Delivery Log'!$S$8:$S$157,'Invoice & Delivery Log'!$B$8:$B$157,$A47)) | N47: =IF($A47="","",IFERROR(COUNTIFS('Invoice & Delivery Log'!$B$8:$B$157,$A47,'Invoice & Delivery Log'!$V$8:$V$157,"On Time")/(COUNTIFS('Invoice & Delivery Log'!$B$8:$B$157,$A47,'Invoice & Delivery Log'!$V$8:$V$157,"On Time")+COUNTIFS('Invoice & Delivery Log'!$B$8:$B$157,$A47,'Invoice & Delivery Log'!$V$8:$V$157,"Late")),"")) | O47: =IF($A47="","",IFERROR(COUNTIFS('Invoice & Delivery Log'!$B$8:$B$157,$A47,'Invoice & Delivery Log'!$K$8:$K$157,"Received in Full")/$I47,"")) | P47: =IF($A47="","",IFERROR(ROUND(AVERAGEIFS('Payments Log'!$L$8:$L$207,'Payments Log'!$C$8:$C$207,$A47,'Payments Log'!$L$8:$L$207,">=0"),0),"")) | Q47: =IF(OR($A47="",$I47=0),"",Settings!$C$14*IF($N47="",0,$N47)+Settings!$C$15*IF($O47="",0,$O47)) | R47: =IF($Q47="","",IF($Q47>=Settings!$C$17,"A",IF($Q47>=Settings!$C$18,"B",IF($Q47>=Settings!$C$19,"C","D")))) | S47: =IF($A47="","",$L47+ROW()/1000000)

Sheet Invoice & Delivery Log
A1: Invoice & Delivery Log
A2: One row per supplier invoice. Record the delivery and the invoice here; record the money on the Payments Log.
A4: Type only in the yellow columns (A-K, N). Everything from L onwards is calculated.
A5: Due Date = Invoice Date + the payment terms held on Vendor Master. Amount Paid is summed from the Payments Log, so part payments update this sheet automatically.
A7: Invoice ID | B7: Vendor ID | C7: Vendor Name | D7: Supplier Invoice No. | E7: PO Number | F7: Category | G7: Description | H7: Invoice Date | I7: Expected Delivery Date | J7: Actual Delivery Date | K7: Goods Receipt Status | L7: Payment Terms (Days) | M7: Due Date | N7: Invoice Amount | O7: Amount Paid | P7: Outstanding Balance | Q7: Payment Status | R7: Days Overdue | S7: Overdue Amount | T7: Aging Bucket | U7: Last Payment Date | V7: Delivery Performance | W7: Data Check | X7: Issue Details | Y7: Open? | Z7: Priority Rank
